Workbook

Sheet szótár_összes
A1: ID | B1: BvdID | C1: Név | D1: Lat | E1: Lon
A2: 1 | B2: HU19308667 | C2: Debreceni Egyetem | D2: =VLOOKUP(B2,geokódok!$B$2:$E$1690,3,FALSE) -> 48.10557 | E2: =VLOOKUP(B2,geokódok!$B$2:$E$1690,4,FALSE) -> 20.79058
A3: 2 | B3: HU15308809 | C3: Miskolci Egyetem | D3: =VLOOKUP(B3,geokódok!$B$2:$E$1690,3,FALSE) -> 47.09252 | E3: =VLOOKUP(B3,geokódok!$B$2:$E$1690,4,FALSE) -> 17.90776
A4: 3 | B4: HU15308816 | C4: Pannon Egyetem | D4: =VLOOKUP(B4,geokódok!$B$2:$E$1690,3,FALSE) -> 47.09252 | E4: =VLOOKUP(B4,geokódok!$B$2:$E$1690,4,FALSE) -> 17.90776
A5: 4 | B5: HU19308681 | C5: Pécsi Tudományegyetem | D5: =VLOOKUP(B5,geokódok!$B$2:$E$1690,3,FALSE) -> 48.10557 | E5: =VLOOKUP(B5,geokódok!$B$2:$E$1690,4,FALSE) -> 20.79058
A6: 5 | B6: HU19308650 | C6: Szegedi Tudományegyetem | D6: =VLOOKUP(B6,geokódok!$B$2:$E$1690,3,FALSE) -> 48.10557 | E6: =VLOOKUP(B6,geokódok!$B$2:$E$1690,4,FALSE) -> 20.79058
A7: 6 | B7: HU19294784 | C7: Magyar Agrár- és Élettudományi Egyetem | D7: =VLOOKUP(B7,geokódok!$B$2:$E$1690,3,FALSE) -> 48.10557 | E7: =VLOOKUP(B7,geokódok!$B$2:$E$1690,4,FALSE) -> 20.79058
A8: 7 | B8: HU15308902 | C8: Széchenyi István Egyetem | D8: =VLOOKUP(B8,geokódok!$B$2:$E$1690,3,FALSE) -> 47.09252 | E8: =VLOOKUP(B8,geokódok!$B$2:$E$1690,4,FALSE) -> 17.90776
A9: 8 | B9: HU19308708 | C9: Nyíregyházi Egyetem | D9: =VLOOKUP(B9,geokódok!$B$2:$E$1690,3,FALSE) -> 48.10557 | E9: =VLOOKUP(B9,geokódok!$B$2:$E$1690,4,FALSE) -> 20.79058
A10: 9 | B10: HU15320988 | C10: Dunaújvárosi Egyetem | D10: =VLOOKUP(B10,geokódok!$B$2:$E$1690,3,FALSE) -> 47.09252 | E10: =VLOOKUP(B10,geokódok!$B$2:$E$1690,4,FALSE) -> 17.90776
A11: 10 | B11: HU15834474 | C11: Neumann János Egyetem | D11: =VLOOKUP(B11,geokódok!$B$2:$E$1690,3,FALSE) -> 47.09252 | E11: =VLOOKUP(B11,geokódok!$B$2:$E$1690,4,FALSE) -> 17.90776
A12: 11 | B12: HU19253086 | C12: Soproni Egyetem | D12: =VLOOKUP(B12,geokódok!$B$2:$E$1690,3,FALSE) -> 48.10557 | E12: =VLOOKUP(B12,geokódok!$B$2:$E$1690,4,FALSE) -> 20.79058
A13: 12 | B13: HU15834481 | C13: Eszterházy Károly Egyetem | D13: =VLOOKUP(B13,geokódok!$B$2:$E$1690,3,FALSE) -> 47.09252 | E13: =VLOOKUP(B13,geokódok!$B$2:$E$1690,4,FALSE) -> 17.90776
... A1555: 1544 | B1555: HU*110187243043 | C1555: DELPHI HUNGARY KFT | D1555: =VLOOKUP(B1555,geokódok!$B$2:$E$1690,3,FALSE) -> 47.22861 | E1555: =VLOOKUP(B1555,geokódok!$B$2:$E$1690,4,FALSE) -> 16.61665
A1556: 1545 | B1556: HU*110231185552 | C1556: ARCONIC-KOFEM KFT | D1556: 47.18874 | E1556: 18.41406
A1557: 1546 | B1557: HU*110309682858 | C1557: CMB CARGO BT | D1557: =VLOOKUP(B1557,geokódok!$B$2:$E$1690,3,FALSE) -> 47.68382 | E1557: =VLOOKUP(B1557,geokódok!$B$2:$E$1690,4,FALSE) -> 17.63567
A1558: 1547 | B1558: HU*110313007114 | C1558: GE HUNGARY KFT. | D1558: 47.65519 | E1558: 19.28712
A1559: 1548 | B1559: HU*226348547 | C1559: I.S.M. PROJECT K.F.T. | D1559: =VLOOKUP(B1559,geokódok!$B$2:$E$1690,3,FALSE) -> 47.114851 | E1559: =VLOOKUP(B1559,geokódok!$B$2:$E$1690,4,FALSE) -> 17.732615
A1560: 1549 | B1560: HU09000022 | C1560: BALLUF-ELEKTRONIKA KFT. | D1560: =VLOOKUP(B1560,geokódok!$B$2:$E$1690,3,FALSE) -> 47.09252 | E1560: =VLOOKUP(B1560,geokódok!$B$2:$E$1690,4,FALSE) -> 17.90776
A1561: 1550 | B1561: FR813157716 | C1561: DENSO GYARTO MAGYARORSZAG KFT | D1561: =VLOOKUP(B1561,geokódok!$B$2:$E$1690,3,FALSE) -> 47.18874 | E1561: =VLOOKUP(B1561,geokódok!$B$2:$E$1690,4,FALSE) -> 18.41406
A1562: 1551 | B1562: HU18915002 | C1562: AVAR AJKA VAROSGAZDALKODASI KFT. SZAKSZERVEZETI BIZOTTSAG | D1562: =VLOOKUP(B1562,geokódok!$B$2:$E$1690,3,FALSE) -> 47.10682 | E1562: =VLOOKUP(B1562,geokódok!$B$2:$E$1690,4,FALSE) -> 17.56397
A1563: 1552 | B1563: HU18920202 | C1563: BADACSONY HEGYKOZSEG | D1563: =VLOOKUP(B1563,geokódok!$B$2:$E$1690,3,FALSE) -> 46.7877 | E1563: =VLOOKUP(B1563,geokódok!$B$2:$E$1690,4,FALSE) -> 17.50508
A1564: 1553 | B1564: HU19189893 | C1564: BALATONI HAJOZASI ZRT. SZAKSZERVEZETE | D1564: =VLOOKUP(B1564,geokódok!$B$2:$E$1690,3,FALSE) -> 46.90696 | E1564: =VLOOKUP(B1564,geokódok!$B$2:$E$1690,4,FALSE) -> 18.05502
A1565: 1554 | B1565: HU27214907 | C1565: "BAKONYVARI" AUTOJAVITO-ALKATRESZELLATO ES SZOLGALTATO BETETI TARSASAG | D1565: =VLOOKUP(B1565,geokódok!$B$2:$E$1690,3,FALSE) -> 47.09252 | E1565: =VLOOKUP(B1565,geokódok!$B$2:$E$1690,4,FALSE) -> 17.90776
A1566: 1555 | B1566: HU57954541 | C1566: BOROS ZSANETT EVA | D1566: =VLOOKUP(B1566,geokódok!$B$2:$E$1690,3,FALSE) -> 46.90543 | E1566: =VLOOKUP(B1566,geokódok!$B$2:$E$1690,4,FALSE) -> 19.68769
A1567: 1556 | B1567: HU11117959 | C1567: AJKAI ELEKTRONIKAI GYARTO ES SZOLGALTATO KORLATOLT FELELOSSEGU TARSASAG | D1567: =VLOOKUP(B1567,geokódok!$B$2:$E$1690,3,FALSE) -> 47.10682 | E1567: =VLOOKUP(B1567,geokódok!$B$2:$E$1690,4,FALSE) -> 17.56397
A1568: 1557 | B1568: HU24268426 | C1568: ADDITIO CONSULTING GAZDASAGI ES PENZUGYI TANACSADO KORLATOLT FELELOSSEGU TARSASAG | D1568: =VLOOKUP(B1568,geokódok!$B$2:$E$1690,3,FALSE) -> 47.09252 | E1568: =VLOOKUP(B1568,geokódok!$B$2:$E$1690,4,FALSE) -> 17.90776
A1569: 1558 | B1569: HU15324683 | C1569: ALLAMI EGESZSEGUGYI ELLATO KOZPONT | D1569: =VLOOKUP(B1569,geokódok!$B$2:$E$1690,3,FALSE) -> 47.49972 | E1569: =VLOOKUP(B1569,geokódok!$B$2:$E$1690,4,FALSE) -> 19.05508
A1570: 1559 | B1570: HU10357547 | C1570: CELLCOMP ELEKTRONIKAI TERMEKEKET GYARTO KORLATOLT FELELOSSEGU TARSASAG | D1570: =VLOOKUP(B1570,geokódok!$B$2:$E$1690,3,FALSE) -> 47.25783 | E1570: =VLOOKUP(B1570,geokódok!$B$2:$E$1690,4,FALSE) -> 17.15223
... A1648: 1637 | B1648: HU12054752-B0001 | C1648: JOHNSON CONTROLS INTERNATIONAL MANUFACTURING AND TRADING LIMITED LIABILITY COMPANY JOHNSON CONTROLS | D1648: =VLOOKUP(B1648,geokódok!$B$2:$E$1690,3,FALSE) -> 47.32833 | E1648: =VLOOKUP(B1648,geokódok!$B$2:$E$1690,4,FALSE) -> 17.46962

Sheet from_to_tip
A1: Honnan (Egyetem) | B1: Hova (Cég) | C1: From | D1: To | J1: BvdID | K1: ID
A2: HU15308816 | B2: HU10660935 | C2: 3 | D2: 14 | J2: HU19308667 | K2: 1
A3: HU15308816 | B3: HU23497980 | C3: 3 | D3: 15 | J3: HU15308809 | K3: 2
A4: HU15308816 | B4: HU10322978 | C4: 3 | D4: 16 | J4: HU15308816 | K4: 3
A5: HU15308816 | B5: HU15300519 | C5: 3 | D5: 17 | J5: HU19308681 | K5: 4
A6: HU15308816 | B6: HU12407954 | C6: 3 | D6: 18 | J6: HU19308650 | K6: 5
A7: HU15308816 | B7: HU14198418 | C7: 3 | D7: 19 | J7: HU19294784 | K7: 6
A8: HU15308816 | B8: HU13978774-B0005 | C8: 3 | D8: 20 | J8: HU15308902 | K8: 7
A9: HU15308816 | B9: HU11912345 | C9: 3 | D9: 21 | J9: HU19308708 | K9: 8
A10: HU15308816 | B10: HU10625790 | C10: 3 | D10: 22 | J10: HU15320988 | K10: 9
A11: HU15308816 | B11: HU12820984 | C11: 3 | D11: 23 | J11: HU15834474 | K11: 10
A12: HU15308816 | B12: HU14482270 | C12: 3 | D12: 24 | J12: HU19253086 | K12: 11
A13: HU15308816 | B13: HU24378776 | C13: 3 | D13: 25 | J13: HU15834481 | K13: 12
... A483: HU15320988 | B483: HU18491263 | C483: 9 | D483: 461 | J483: HU10970791 | K483: 472
J484: HU25539448 | K484: 473
J485: HU28975375 | K485: 474
J486: HU19820851 | K486: 475
J487: HU10263332 | K487: 476
J488: HU10241662 | K488: 477
J489: HU12136849 | K489: 478
J490: HU10256161 | K490: 479
J491: HU18933974 | K491: 480
J492: HU14823495 | K492: 481
J493: HU14915842 | K493: 482
J494: HU24277338 | K494: 483
J495: HU10359185 | K495: 484
... J1648: HU12054752-B0001 | K1648: 1637

Sheet from_to_dualis
A1: Honnan (Egyetem) | B1: Hova (Cég) | C1: From | D1: To | J1: BvdID | K1: ID
A2: HU15329743 | B2: HU19820387 | C2: 13 | D2: 462 | J2: HU19308667 | K2: 1
A3: HU15329743 | B3: HU10725199 | C3: 13 | D3: 463 | J3: HU15308809 | K3: 2
A4: HU15329743 | B4: HU18079519 | C4: 13 | D4: 464 | J4: HU15308816 | K4: 3
A5: HU15329743 | B5: HU19806567 | C5: 13 | D5: 465 | J5: HU19308681 | K5: 4
A6: HU15329743 | B6: HU25442113 | C6: 13 | D6: 466 | J6: HU19308650 | K6: 5
A7: HU15329743 | B7: HU12255764 | C7: 13 | D7: 375 | J7: HU19294784 | K7: 6
A8: HU15329743 | B8: HU10443785 | C8: 13 | D8: 467 | J8: HU15308902 | K8: 7
A9: HU15329743 | B9: HU11108322 | C9: 13 | D9: 468 | J9: HU19308708 | K9: 8
A10: HU15329743 | B10: HU10907836 | C10: 13 | D10: 469 | J10: HU15320988 | K10: 9
A11: HU15329743 | B11: HU22782537 | C11: 13 | D11: 470 | J11: HU15834474 | K11: 10
A12: HU15329743 | B12: HU14300011 | C12: 13 | D12: 471 | J12: HU19253086 | K12: 11
A13: HU15329743 | B13: HU10970791 | C13: 13 | D13: 472 | J13: HU15834481 | K13: 12
... A576: HU15308816 | B576: HU11231240 | C576: 3 | D576: 904 | J576: HU25103234 | K576: 565
J577: HU12154481 | K577: 566
J578: HU11102539 | K578: 567
J579: HU10856417 | K579: 568
J580: HU13834492 | K580: 569
J581: HU14130179 | K581: 570
J582: HU13649588 | K582: 571
J583: HU11194185 | K583: 572
J584: HU10274837 | K584: 573
J585: HU24325792 | K585: 574
J586: HU11878513 | K586: 575
J587: HU24325668 | K587: 576
J588: HU10417823 | K588: 577
... J1648: HU12054752-B0001 | K1648: 1637

Sheet from_to_szakgyak
A1: Honnan (Egyetem) | B1: Hova (Cég) | C1: From | D1: To | J1: BvdID | K1: ID
A2: HU15308816 | B2: HU11181815 | C2: 3 | D2: 485 | J2: HU19308667 | K2: 1
A3: HU15308816 | B3: HU25045675 | C3: 3 | D3: 905 | J3: HU15308809 | K3: 2
A4: HU15308816 | B4: HU10233342 | C4: 3 | D4: 906 | J4: HU15308816 | K4: 3
A5: HU15308816 | B5: HU12500909 | C5: 3 | D5: 900 | J5: HU19308681 | K5: 4
A6: HU15308816 | B6: HU23424379 | C6: 3 | D6: 907 | J6: HU19308650 | K6: 5
A7: HU15308816 | B7: HU25337703 | C7: 3 | D7: 908 | J7: HU19294784 | K7: 6
A8: HU15308816 | B8: HU11524465 | C8: 3 | D8: 865 | J8: HU15308902 | K8: 7
A9: HU15308816 | B9: HU13894427 | C9: 3 | D9: 909 | J9: HU19308708 | K9: 8
A10: HU15308816 | B10: HU15803586 | C10: 3 | D10: 910 | J10: HU15320988 | K10: 9
A11: HU15308816 | B11: HU23546730 | C11: 3 | D11: 911 | J11: HU15834474 | K11: 10
A12: HU15308816 | B12: HU15808457 | C12: 3 | D12: 912 | J12: HU19253086 | K12: 11
A13: HU15308816 | B13: HU10742833 | C13: 3 | D13: 913 | J13: HU15834481 | K13: 12
... A799: HU15308816 | B799: HU12054752-B0001 | C799: 3 | D799: 1637 | J799: HU14925889 | K799: 788
J800: HU11013714 | K800: 789
J801: HU10824346-B0177 | K801: 790
J802: HU11541484 | K802: 791
J803: HU11292393 | K803: 792
J804: HU10264869 | K804: 793
J805: HU10450633 | K805: 794
J806: HU13311207 | K806: 795
J807: HU11317960 | K807: 796
J808: HU12282225 | K808: 797
J809: HU12638145 | K809: 798
J810: HU11302526 | K810: 799
J811: HU10008676 | K811: 800
... J1648: HU12054752-B0001 | K1648: 1637

Sheet geokódok
A1: Egyetemek/cégek | B1: BvD ID | C1: City | D1: lat | E1: lon
A2: Debreceni Egyetem | B2: HU19308667 | C2: =VLOOKUP(B2,[1]Atis_geocodes!$C$2:$F$1234,4) -> MISKOLC | D2: 48.10557 | E2: 20.79058
A3: Miskolci Egyetem | B3: HU15308809 | C3: =VLOOKUP(B3,[1]Atis_geocodes!$C$2:$F$1234,4) -> VESZPREM | D3: =VLOOKUP(C3,[1]Atis_geocodes!F2:H474,3,FALSE) -> 47.09252 | E3: =VLOOKUP(C3,[1]Atis_geocodes!F2:I474,4,FALSE) -> 17.90776
A4: Pannon Egyetem | B4: HU15308816 | C4: =VLOOKUP(B4,[1]Atis_geocodes!$C$2:$F$1234,4) -> VESZPREM | D4: =VLOOKUP(C4,[1]Atis_geocodes!F3:H475,3,FALSE) -> 47.09252 | E4: =VLOOKUP(C4,[1]Atis_geocodes!F3:I475,4,FALSE) -> 17.90776
A5: Pécsi Tudományegyetem | B5: HU19308681 | C5: =VLOOKUP(B5,[1]Atis_geocodes!$C$2:$F$1234,4) -> MISKOLC | D5: 48.10557 | E5: 20.79058
A6: Szegedi Tudományegyetem | B6: HU19308650 | C6: =VLOOKUP(B6,[1]Atis_geocodes!$C$2:$F$1234,4) -> MISKOLC | D6: 48.10557 | E6: 20.79058
A7: Magyar Agrár- és Élettudományi Egyetem | B7: HU19294784 | C7: =VLOOKUP(B7,[1]Atis_geocodes!$C$2:$F$1234,4) -> MISKOLC | D7: 48.10557 | E7: 20.79058
A8: Széchenyi István Egyetem | B8: HU15308902 | C8: =VLOOKUP(B8,[1]Atis_geocodes!$C$2:$F$1234,4) -> VESZPREM | D8: =VLOOKUP(C8,[1]Atis_geocodes!F7:H479,3,FALSE) -> 47.09252 | E8: =VLOOKUP(C8,[1]Atis_geocodes!F7:I479,4,FALSE) -> 17.90776
A9: Nyíregyházi Egyetem | B9: HU19308708 | C9: =VLOOKUP(B9,[1]Atis_geocodes!$C$2:$F$1234,4) -> MISKOLC | D9: 48.10557 | E9: 20.79058
A10: Dunaújvárosi Egyetem | B10: HU15320988 | C10: =VLOOKUP(B10,[1]Atis_geocodes!$C$2:$F$1234,4) -> VESZPREM | D10: =VLOOKUP(C10,[1]Atis_geocodes!F9:H481,3,FALSE) -> 47.09252 | E10: =VLOOKUP(C10,[1]Atis_geocodes!F9:I481,4,FALSE) -> 17.90776
A11: Neumann János Egyetem | B11: HU15834474 | C11: =VLOOKUP(B11,[1]Atis_geocodes!$C$2:$F$1234,4) -> VESZPREM | D11: =VLOOKUP(C11,[1]Atis_geocodes!F10:H482,3,FALSE) -> 47.09252 | E11: =VLOOKUP(C11,[1]Atis_geocodes!F10:I482,4,FALSE) -> 17.90776
A12: Soproni Egyetem | B12: HU19253086 | C12: =VLOOKUP(B12,[1]Atis_geocodes!$C$2:$F$1234,4) -> MISKOLC | D12: 48.10557 | E12: 20.79058
A13: Eszterházy Károly Egyetem | B13: HU15834481 | C13: =VLOOKUP(B13,[1]Atis_geocodes!$C$2:$F$1234,4) -> VESZPREM | D13: =VLOOKUP(C13,[1]Atis_geocodes!F12:H484,3,FALSE) -> 47.09252 | E13: =VLOOKUP(C13,[1]Atis_geocodes!F12:I484,4,FALSE) -> 17.90776
A14: Budapesti egyetemek | B14: Budapesti | C14: =VLOOKUP(B14,[1]Atis_geocodes!$C$2:$F$1234,4) -> LINZ | D14: =VLOOKUP(C14,[1]Atis_geocodes!F13:H485,3,FALSE) -> 48.30422 | E14: =VLOOKUP(C14,[1]Atis_geocodes!F13:I485,4,FALSE) -> 14.28816
A15: CONTROLSOFT-AUTOMATIKA SZOLGALTATO KORLATOLT FELELOSSEGU TARSASAG | B15: HU10660935 | C15: =VLOOKUP(B15,[1]Atis_geocodes!$C$2:$F$1234,4) -> BUDAPEST | D15: =VLOOKUP(C15,[1]Atis_geocodes!F14:H486,3,FALSE) -> 47.49972 | E15: =VLOOKUP(C15,[1]Atis_geocodes!F14:I486,4,FALSE) -> 19.05508
A16: BAY ZOLTAN ALKALMAZOTT KUTATASI KOZHASZNU NONPROFIT KORLATOLT FELELOSSEGU TARSASAG | B16: HU23497980 | C16: =VLOOKUP(B16,[1]Atis_geocodes!$C$2:$F$1234,4) -> MISKOLC | D16: 48.10557 | E16: 20.79058
A17: HIDROFILT VIZKEZELEST TERVEZO ES KIVITELEZO KORLATOLT FELELOSSEGU TARSASAG | B17: HU10322978 | C17: =VLOOKUP(B17,[1]Atis_geocodes!$C$2:$F$1234,4) -> LINZ | D17: =VLOOKUP(C17,[1]Atis_geocodes!F16:H488,3,FALSE) -> 48.30422 | E17: =VLOOKUP(C17,[1]Atis_geocodes!F16:I488,4,FALSE) -> 14.28816
A18: AGRARTUDOMANYI KUTATOKOZPONT | B18: HU15300519 | C18: =VLOOKUP(B18,[1]Atis_geocodes!$C$2:$F$1234,4) -> VESZPREM | D18: =VLOOKUP(C18,[1]Atis_geocodes!F17:H489,3,FALSE) -> 47.09252 | E18: =VLOOKUP(C18,[1]Atis_geocodes!F17:I489,4,FALSE) -> 17.90776
A19: GONDOS AGRIKULTURA KORLATOLT FELELOSSEGU TARSASAG | B19: HU12407954 | C19: =VLOOKUP(B19,[1]Atis_geocodes!$C$2:$F$1234,4) -> BUDAPEST | D19: =VLOOKUP(C19,[1]Atis_geocodes!F18:H490,3,FALSE) -> 47.49972 | E19: =VLOOKUP(C19,[1]Atis_geocodes!F18:I490,4,FALSE) -> 19.05508
A20: KDRIU KOZEP-DUNANTULI REGIONALIS INNOVACIOS UGYNOKSEG NONPROFIT KORLATOLT FELELOSSEGU TARSASAG | B20: HU14198418 | C20: =VLOOKUP(B20,[1]Atis_geocodes!$C$2:$F$1234,4) -> BUDAPEST | D20: =VLOOKUP(C20,[1]Atis_geocodes!F19:H491,3,FALSE) -> 47.49988 | E20: =VLOOKUP(C20,[1]Atis_geocodes!F19:I491,4,FALSE) -> 19.02617
A21: DELTA SYSTEMS KORLATOLT FELELOSSEGU TARSASAG - VESZPREM | B21: HU13978774-B0005 | C21: =VLOOKUP(B21,[1]Atis_geocodes!$C$2:$F$1234,4) -> BUDAPEST | D21: =VLOOKUP(C21,[1]Atis_geocodes!F20:H492,3,FALSE) -> 47.49704 | E21: =VLOOKUP(C21,[1]Atis_geocodes!F20:I492,4,FALSE) -> 19.03207
A22: LAVINA SZERVIZ KERESKEDELMI ES SZOLGALTATO KORLATOLT FELELOSSEGU TARSASAG | B22: HU11912345 | C22: =VLOOKUP(B22,[1]Atis_geocodes!$C$2:$F$1234,4) -> BUDAPEST | D22: =VLOOKUP(C22,[1]Atis_geocodes!F21:H493,3,FALSE) -> 47.49704 | E22: =VLOOKUP(C22,[1]Atis_geocodes!F21:I493,4,FALSE) -> 19.03207
A23: MOL MAGYAR OLAJ-ES GAZIPARE RESZVENYTAR | B23: HU10625790 | C23: =VLOOKUP(B23,[1]Atis_geocodes!$C$2:$F$1234,4) -> KESZTHELY | D23: =VLOOKUP(C23,[1]Atis_geocodes!F22:H494,3,FALSE) -> 46.76296 | E23: =VLOOKUP(C23,[1]Atis_geocodes!F22:I494,4,FALSE) -> 17.24256
A24: ADIENT MEZOLAK KORLATOLT FELELOSSEGU TARSASAG | B24: HU12820984 | C24: =VLOOKUP(B24,[1]Atis_geocodes!$C$2:$F$1234,4) -> BUDAPEST | D24: =VLOOKUP(C24,[1]Atis_geocodes!F23:H495,3,FALSE) -> 47.49704 | E24: =VLOOKUP(C24,[1]Atis_geocodes!F23:I495,4,FALSE) -> 19.03207
A25: NAGYKANIZSA VAGYONGAZDALKODASI ES SZOLGALTATO ZARTKORUEN MUKODO RESZVENYTARSASAG | B25: HU14482270 | C25: =VLOOKUP(B25,[1]Atis_geocodes!$C$2:$F$1234,4) -> BUDAPEST | D25: =VLOOKUP(C25,[1]Atis_geocodes!F24:H496,3,FALSE) -> 47.49972 | E25: =VLOOKUP(C25,[1]Atis_geocodes!F24:I496,4,FALSE) -> 19.05508
A26: MAGYAR KORUT KORLATOLT FELELOSSEGU TARSASAG | B26: HU24378776 | C26: =VLOOKUP(B26,[1]Atis_geocodes!$C$2:$F$1234,4) -> MISKOLC | D26: 48.10557 | E26: 20.79058
A27: MARTIN METALS KERESKEDELMI KORLATOLT FELELOSSEGU TARSASAG | B27: HU13108809 | C27: =VLOOKUP(B27,[1]Atis_geocodes!$C$2:$F$1234,4) -> BUDAPEST | D27: =VLOOKUP(C27,[1]Atis_geocodes!F26:H498,3,FALSE) -> 47.50251 | E27: =VLOOKUP(C27,[1]Atis_geocodes!F26:I498,4,FALSE) -> 19.03358
A28: VESZPREM MEGYEI KERESKEDELMI ES IPARKAMARA | B28: HU18917815 | C28: =VLOOKUP(B28,[1]Atis_geocodes!$C$2:$F$1234,4) -> VESZPREM | D28: =VLOOKUP(C28,[1]Atis_geocodes!F27:H499,3,FALSE) -> 47.09252 | E28: =VLOOKUP(C28,[1]Atis_geocodes!F27:I499,4,FALSE) -> 17.90776
A29: PMG HUNGARY KORLATOLT FELELOSSEGU TARSASAG | B29: HU23806072 | C29: =VLOOKUP(B29,[1]Atis_geocodes!$C$2:$F$1234,4) -> MISKOLC | D29: 48.10557 | E29: 20.79058
A30: VESZPREMTERV INGATLANKEZELO KORLATOLT FELELOSSEGU TARSASAG | B30: HU26248699 | C30: VESZPREM | D30: =VLOOKUP(C30,[1]Atis_geocodes!F29:H501,3,FALSE) -> 47.09252 | E30: =VLOOKUP(C30,[1]Atis_geocodes!F29:I501,4,FALSE) -> 17.90776
A31: PARAFIX HUNGARIA IPARI ES KERESKEDELMI KORLATOLT FELELOSSEGU TARSASAG | B31: HU12539558 | C31: =VLOOKUP(B31,[1]Atis_geocodes!$C$2:$F$1234,4) -> BUDAPEST | D31: =VLOOKUP(C31,[1]Atis_geocodes!F30:H502,3,FALSE) -> 47.50251 | E31: =VLOOKUP(C31,[1]Atis_geocodes!F30:I502,4,FALSE) -> 19.03358
A32: NN ENERGETIKAI MEGOLDASOK KORLATOLT FELELOSSEGU TARSASAG | B32: HU23833650 | C32: =VLOOKUP(B32,[1]Atis_geocodes!$C$2:$F$1234,4) -> MISKOLC | D32: 48.10557 | E32: 20.79058
A33: MKB CONSULTING ZARTKORUEN MUKODO RESZVENYTARSASAG - BUDAPEST | B33: HU27942592 | C33: BUDAPEST | D33: =VLOOKUP(C33,[1]Atis_geocodes!F32:H504,3,FALSE) -> 47.50251 | E33: =VLOOKUP(C33,[1]Atis_geocodes!F32:I504,4,FALSE) -> 19.03358
A34: "KATA CNC" IPARI ES KERESKEDELMI KORLATOLT FELELOSSEGU TARSASAG | B34: HU12324718 | C34: =VLOOKUP(B34,[1]Atis_geocodes!$C$2:$F$1234,4) -> BUDAPEST | D34: =VLOOKUP(C34,[1]Atis_geocodes!F33:H505,3,FALSE) -> 47.50251 | E34: =VLOOKUP(C34,[1]Atis_geocodes!F33:I505,4,FALSE) -> 19.03358
A35: VFP SYSTEMS KERESKEDELMI ES SZOLGALTATO KORLATOLT FELELOSSEGU TARSASAG | B35: HU23128073 | C35: =VLOOKUP(B35,[1]Atis_geocodes!$C$2:$F$1234,4) -> MISKOLC | D35: 48.10557 | E35: 20.79058
A36: BIOCENTRUM KORNYEZETVEDELMI ES VIZGAZDALKODASI KORLATOLT FELELOSSEGU TARSASAG | B36: HU11753795 | C36: =VLOOKUP(B36,[1]Atis_geocodes!$C$2:$F$1234,4) -> BUDAPEST | D36: =VLOOKUP(C36,[1]Atis_geocodes!F35:H507,3,FALSE) -> 47.49972 | E36: =VLOOKUP(C36,[1]Atis_geocodes!F35:I507,4,FALSE) -> 19.05508
A37: FLEXMONT SZERELESTECHNIKAI ES AUTOMATIZALASI KORLATOLT FELELOSSEGU TARSASAG | B37: HU11323604 | C37: =VLOOKUP(B37,[1]Atis_geocodes!$C$2:$F$1234,4) -> BUDAPEST | D37: =VLOOKUP(C37,[1]Atis_geocodes!F36:H508,3,FALSE) -> 47.49972 | E37: =VLOOKUP(C37,[1]Atis_geocodes!F36:I508,4,FALSE) -> 19.05508
A38: NAGYKANIZSAI KERESKEDELMI ES IPARKAMARA | B38: HU18963373 | C38: =VLOOKUP(B38,[1]Atis_geocodes!$C$2:$F$1234,4) -> MISKOLC | D38: 48.10557 | E38: 20.79058
A39: SQS 2001. KERESKEDELMI ES SZOLGALTATO KORLATOLT FELELOSSEGU TARSASAG | B39: HU12620667 | C39: =VLOOKUP(B39,[1]Atis_geocodes!$C$2:$F$1234,4) -> BUDAPEST | D39: =VLOOKUP(C39,[1]Atis_geocodes!F38:H510,3,FALSE) -> 47.49972 | E39: =VLOOKUP(C39,[1]Atis_geocodes!F38:I510,4,FALSE) -> 19.05508
A40: VIRGO SYSTEMS INFORMATIKAI KORLATOLT FELELOSSEGU TARSASAG | B40: HU12497278-B0002 | C40: =VLOOKUP(B40,[1]Atis_geocodes!$C$2:$F$1234,4) -> BUDAPEST | D40: =VLOOKUP(C40,[1]Atis_geocodes!F39:H511,3,FALSE) -> 47.49972 | E40: =VLOOKUP(C40,[1]Atis_geocodes!F39:I511,4,FALSE) -> 19.05508
...
