Workbook

Sheet Munka1
A1: Company name Latin alphabet | B1: BvD ID number | F1: Company name Latin alphabet | G1: BvD ID number | K1: budapesti | L1: Állatorvostudományi Egyetem, a Budapesti Corvinus Egyetem, a Budapesti Műszaki és Gazdaságtudományi Egyetem, az Eötvös Lóránd Tudományegyetem, Magyar Képzőművészeti Egyetem, Moholy-Nagy Művészeti Egyetem, Nemzeti Közszolgálati Egyetem, az Óbudai Egyetem, a Semmelweis Egyetem, a Színház és Filmművészeti Egyetem és a Testnevelési Egyetem.
A2: Debreceni Egyetem | B2: HU19308667 | E2: 1. | F2: HOTEL KOLPING GESELLSCHAFT M.B.H. | G2: AT9070074760 | K2: debreceni
A3: Miskolci Egyetem | B3: HU15308809 | E3: 2. | F3: TATA CONSULTANCY SERVICES DEUTSCHLAND GMBH | G3: DE6070209254 | K3: dunaújvárosi
A4: PE | B4: HU15308816 | E4: 500. | F4: SAP SE | G4: DE7050001788 | K4: egri
A5: PTE | B5: HU19308681 | E5: 507. | F5: ZIEHL-ABEGG SE | G5: DE7070181890 | K5: gödöllői
A6: SZTE | B6: HU19308650 | E6: 10. | F6: HARMAN BECKER AUTOMOTIVE SYSTEMS GMBH | G6: DE7230115066 | K6: győri
A7: MATE | B7: HU19294784 | E7: 1. | F7: AUDI AG | G7: DE8130008438 | K7: kecskeméti
A8: SZIE | B8: HU15308902 | E8: 499. | F8: UNILEVER PLC | G8: GB00041424 | K8: miskolci
A9: Nyíregyházi Egyetem | B9: HU19308708 | E9: 12. | F9: BOEING COMMERCIAL AVIATION SERVICES EUROPE LIMITED | G9: GB08186759 | K9: nyíregyházi
A10: Dunaújvárosi Egyetem | B10: HU15320988 | E10: 775. | F10: SZOVETKEZETI SZOLGALTATO ZRT BALATONFOI | G10: HU*110000107540 | K10: pécsi
A11: Neumann János Egyetem | B11: HU15834474 | E11: 776. | F11: PAPA ES VIDEKE AFESZ | G11: HU*110009451762 | K11: soproni
A12: Soproni Egyetem | B12: HU19253086 | E12: 456. | F12: DELPHI HUNGARY KFT | G12: HU*110187243043 | K12: szegedi
A13: Eszterházy Károly Egyetem | B13: HU15834481 | E13: 457. | F13: ARCONIC-KOFEM KFT | G13: HU*110231185552 | K13: pannon
A14: Budepesti egyetemek | B14: budapesti | E14: 458. | F14: CMB CARGO BT | G14: HU*110309682858 | K14: céges_EMM lista | L14: NEM TIP-ES NINCS A TOVÁBBI FÜLEKEN
E15: 459. | F15: GE HUNGARY KFT. | G15: HU*110313007114
E16: 777. | F16: SZEKESFEHERVAR MEGYEI JOGU VAROS POLGARMESTERI HIVATAL | G16: HU*138911
E17: 460. | F17: I.S.M. PROJECT K.F.T. | G17: HU*226348547
E18: 461. | F18: BALLUF-ELEKTRONIKA KFT. | G18: HU09000022
E19: 209. | F19: KORMEND ES VIDEKE AFESZ | G19: HU10042164
E20: 24. | F20: CIB BANK LTD | G20: HU10136915
E21: 462. | F21: CIB BANK ZRT. | G21: HU10136915-B0062
E22: 229. | F22: CLUB TIHANY UDULOKOZPONT ZARTKORUEN MUKODO RESZVENYTARSASAG | G22: HU10187186
E23: 14. | F23: K&H BANK ZRT | G23: HU10195664
E24: 19. | F24: BUDAPEST BANK NYRT | G24: HU10196445
E25: 16. | F25: ERSTE BANK HUNGARY ZRT | G25: HU10197879
E26: 635. | F26: TALENTUM KONYVES ES KERESKEDO KFT. | G26: HU10224454
... E824: 246. | F824: HOTEL MARINA, HOTELI IN TURIZEM, D.O.O. | G824: SI2226421
E825: 824. | F825: ZALA MEGYEI KERESKEDELMI ES IPARKAMARA SZOLGALTATO KORLATOLT FELELOSSEGU TARSASAG
E826: 825. | F826: HOLL & MOOR EGESZSEGUGYI SZOLGALTATO ES TANACSADO KORLATOLT FELELOSSEGU TARSASAG
E827: 826. | F827: ORGONMED KORLATOLT FELELOSSEGU TARSASAG
E828: 827. | F828: PANNON INNOVATION AGENCY KORLATOLT FELELOSSEGU TARSASAG
E829: 828. | F829: TUNGSRAM OPERATIONS KFT.
E830: 829. | F830: STATCOG INFORMATIKAI KORLATOLT FELELOSSEGU TARSASAG
E831: 830. | F831: ARCHENERG KORLATOLT FELELOSSEGU TARSASAG
E832: 831. | F832: AH NET TAVKOZLESI SZOLGALTATO ZARTKORUEN MUKODO RESZVENYTARSASAG | G832: HU23843862
E833: 832. | F833: DELTA SYSTEMS KORLATOLT FELELOSSEGU TARSASAG | G833: HU13978774
E834: 833. | F834: 3DHISTECH FEJLESZTO KORLATOLT FELELOSSEGU TARSASAG | G834: HU10620386
E835: 834. | F835: PROLAN IRANYITASTECHNIKAI ZARTKORUEN MUKODO RESZVENYTARSASAG | G835: HU12351846
E836: 835. | F836: K9-SPORT KERESKEDELMI ES SZOLGALTATO KORLATOLT FELELOSSEGU TARSASAG | G836: HU14762345
E837: 836. | F837: SANATMETAL ORTOPEDIAI ES TRAUMATOLOGIAI ESZKOZOKET GYARTO KORLATOLT FELELOSSEGU TARSASAG | G837: HU11172790
...

Sheet városok
A1: Company name Latin alphabet | B1: BvD ID number | C1: NUTS3 | D1: Standardized city | E1: City Latin Alphabet
A2: AUDI AG | B2: DE8130008438 | D2: INGOLSTADT | E2: INGOLSTADT
A3: UNILEVER PLC | B3: GB00041424 | C3: UKD74 - Wirral | E3: WIRRAL
A4: SAP SE | B4: DE7050001788 | C4: DE128 - Rhein-Neckar | D4: WALLDORF | E4: WALLDORF
A5: MOL MAGYAR OLAJ-ES GAZIPARE RESZVENYTAR | B5: HU10625790 | C5: HU110 - Budapest | D5: BUDAPEST | E5: BUDAPEST
A6: OTP BANK PLC | B6: HU10537914 | C6: HU110 - Budapest | D6: BUDAPEST | E6: BUDAPEST
A7: MERCEDES-BENZ MANUFACTURING HUNGARY KORLATOLT FELELOSSEGU TARSASAG | B7: HU14398649 | C7: HU331 - Bacs-Kiskun megye | D7: KECSKEMÉT | E7: KECSKEMET
A8: MAV MAGYAR ALLAMVASUTAK ZARTKORUEN MUKODO RESZVENYTARSASAG | B8: HU10856417 | C8: HU110 - Budapest | D8: BUDAPEST | E8: BUDAPEST
A9: FLEXTRONICS INTERNATIONAL MANUFACTURING AND SERVICES DUTY-FREE ZONE LIMITED LIABILITY COMPANY, FLEXTRONICS INTERNATIONAL LLC | B9: HU11222149 | C9: HU232 - Somogy megye | D9: TAB | E9: TAB
A10: HUNGAROPHARMA GYOGYSZERKERESKEDELMI ZARTKORUEN MUKODO RESZVENYTARSASAG | B10: HU10875933 | C10: HU110 - Budapest | D10: BUDAPEST | E10: BUDAPEST
A11: CONTINENTAL AUTOMOTIVE HUNGARY LIMITED LIABILITY COMPANY, CONTINENTAL AUTOMOTIVE HUNGARY LTD. | B11: HU10518869 | C11: HU213 - Veszprem megye | D11: VESZPRÉM | E11: VESZPREM
A12: AUCHAN MAGYARORSZAG KERESKEDELMI ES SZOLGALTATO KORLATOLT FELELOSSEGU TARSASAG | B12: HU13338037 | C12: HU120 - Pest | D12: BUDAÖRS | E12: BUDAORS
A13: BOEING COMMERCIAL AVIATION SERVICES EUROPE LIMITED | B13: GB08186759 | C13: UKI32 - Westminster | E13: LONDON
A14: HARMAN BECKER AUTOMOTIVE SYSTEMS GMBH | B14: DE7230115066 | C14: DE123 - Karlsruhe, Landkreis | D14: KARLSBAD | E14: KARLSBAD
A15: IBM DATA STORAGE SYSTEMS IPARI VAMSZABADTERULETI KFT. (IBM DSS KFT.) | B15: HU1309093701 | E15: VAC
A16: TATA CONSULTANCY SERVICES DEUTSCHLAND GMBH | B16: DE6070209254 | C16: DE712 - Frankfurt am Main | D16: FRANKFURT AM MAIN | E16: FRANKFURT
A17: VIDEOTON HOLDING ZARTKORUEN MUKODO RESZVENYTARSASAG | B17: HU11181815 | C17: HU211 - Fejer megye | D17: SZÉKESFEHÉRVÁR | E17: SZEKESFEHERVAR
A18: EGIS GYOGYSZERGYAR ZARTKORUEN MUKODO RESZVENYTARSASAG | B18: HU10686506 | C18: HU110 - Budapest | D18: BUDAPEST | E18: BUDAPEST
A19: K&H BANK ZRT | B19: HU10195664 | D19: BUDAPEST | E19: BUDAPEST
A20: VALEO AUTO-ELECTRIC MAGYARORSZAG GEPJARMUALKATRESZ-GYARTO KORLATOLT FELELOSSEGU TARSASAG | B20: HU11761606 | C20: HU213 - Veszprem megye | D20: VESZPRÉM | E20: VESZPREM
A21: MVM PAKSI ATOMEROMU ZARTKORUEN MUKODO RESZVENYTARSASAG | B21: HU10742833 | C21: HU233 - Tolna megye | D21: PAKS | E21: PAKS
A22: ZIEHL-ABEGG SE | B22: DE7070181890 | C22: DE119 - Hohenlohe | D22: KÜNZELSAU | E22: KUENZELSAU
A23: ERSTE BANK HUNGARY ZRT | B23: HU10197879 | D23: BUDAPEST | E23: BUDAPEST
A24: NESTLE HUNGARIA KFT | B24: HU10571086 | C24: HU110 - Budapest | D24: BUDAPEST | E24: BUDAPEST
A25: HYDRO EXTRUSION HUNGARY KORLATOLT FELELOSSEGU TARSASAG | B25: HU13913483 | C25: HU211 - Fejer megye | D25: SZÉKESFEHÉRVÁR | E25: SZEKESFEHERVAR
A26: MVM MATRA ENERGIA ZARTKORUEN MUKODO RESZVENYTARSASAG | B26: HU10729571 | C26: HU312 - Heves megye | D26: VISONTA | E26: VISONTA
A27: BPW-HUNGARIA KORLATOLT FELELOSSEGU TARSASAG | B27: HU10575561 | C27: HU222 - Vas megye | D27: SZOMBATHELY | E27: SZOMBATHELY
A28: BUDAPEST BANK NYRT | B28: HU10196445 | C28: HU110 - Budapest | D28: BUDAPEST | E28: BUDAPEST V
A29: ADIENT MEZOLAK KORLATOLT FELELOSSEGU TARSASAG | B29: HU12820984 | C29: HU213 - Veszprem megye | D29: MEZOLAK | E29: MEZOLAK
A30: NITROGENMUVEK VEGYIPARI ZARTKORUEN MUKODO RESZVENYTARSASAG | B30: HU10325957 | C30: HU213 - Veszprem megye | D30: PÉTFÜRDO | E30: PETFURDO
A31: LINDE GAZ MAGYARORSZAG ZARTKORUEN MUKODO RESZVENYTARSASAG | B31: HU11300184 | C31: HU222 - Vas megye | D31: RÉPCELAK | E31: REPCELAK
A32: ALCUFER IPARI KERESKEDELMI ES SZOLGALTATO KORLATOLT FELELOSSEGU TARSASAG | B32: HU10356962 | C32: HU221 - Gyor-Sopron-Moson megye | D32: GYOR | E32: GYOR
A33: CIB BANK LTD | B33: HU10136915 | C33: HU110 - Budapest | D33: BUDAPEST | E33: BUDAPEST
A34: TYCO ELECTRONICS HUNGARY TERMELO KORLATOLT FELELOSSEGU TARSASAG | B34: HU11185871 | C34: HU212 - Komarom-Esztergom megye | D34: ESZTERGOM | E34: ESZTERGOM
A35: HANON SYSTEMS HUNGARY KORLATOLT FELELOSSEGU TARSASAG | B35: HU10413214 | C35: HU211 - Fejer megye | D35: SZÉKESFEHÉRVÁR | E35: SZEKESFEHERVAR
... A65: SZENTKIRALYI MAGYARORSZAG KERESKEDELMI ES TERMELO KORLATOLT FELELOSSEGU TARSASAG | B65: HU13079026 | C65: HU110 - Budapest | D65: BUDAPEST | E65: BUDAPEST
A66: BOCK HUNGARIA IPARI ES KERESKEDELMI KORLATOLT FELELOSSEGU TARSASAG | B66: HU12880706 | C66: HU213 - Veszprem megye | E66: NOSZLOP
A67: LISS PATRONGYARTO, TOLTO ES FORGALMAZO KORLATOLT FELELOSSEGU TARSASAG | B67: HU12639366 | C67: HU222 - Vas megye | D67: RÉPCELAK | E67: REPCELAK
A68: MAM-HUNGARIA IPARI ES KERESKEDELMI KORLATOLT FELELOSSEGU TARSASAG | B68: HU10444061 | C68: HU222 - Vas megye | D68: VASKERESZTES | E68: VASKERESZTES
A69: KPMG HUNGARIA KONYVVIZSGALO, ADO- ES KOZGAZDASAGI TANACSADO KORLATOLT FELELOSSEGU TARSASAG | B69: HU10263332 | C69: HU110 - Budapest | D69: BUDAPEST | E69: BUDAPEST
...

Sheet szótár
A1: ID | B1: Name | C1: BvDID
A2: 1 | B2: Debreceni Egyetem | C2: HU19308667
A3: 2 | B3: Miskolci Egyetem | C3: HU15308809
A4: 3 | B4: Pannon Egyetem | C4: HU15308816
A5: 4 | B5: Pécsi Tudományegyetem | C5: HU19308681
A6: 5 | B6: Szegedi Tudományegyetem | C6: HU19308650
A7: 6 | B7: Magyar Agrár- és Élettudományi Egyetem | C7: HU19294784
A8: 7 | B8: Széchenyi István Egyetem | C8: HU15308902
A9: 8 | B9: Nyíregyházi Egyetem | C9: HU19308708
A10: 9 | B10: Dunaújvárosi Egyetem | C10: HU15320988
A11: 10 | B11: Neumann János Egyetem | C11: HU15834474
A12: 11 | B12: Soproni Egyetem | C12: HU19253086
A13: 12 | B13: Eszterházy Károly Egyetem | C13: HU15834481
... A465: 464 | B465: DUNAUJVAROS MEGYEI JOGU VAROS KERESKEDELMI ES IPARKAMARA | C465: HU18491263

Sheet from_to
A1: Honnan (Egyetem) | B1: Hova (Cég) | C1: From | D1: To | E1: BvD ID | F1: No.
A2: HU15308816 | B2: HU11753795 | C2: =VLOOKUP(A2,$E$2:$F$465,2,FALSE) -> 3 | D2: =VLOOKUP(B2,$E$2:$F$465,2,FALSE) -> 14 | E2: HU19308667 | F2: 1
A3: HU15308816 | B3: HU11912345 | C3: =VLOOKUP(A3,$E$2:$F$465,2,FALSE) -> 3 | D3: =VLOOKUP(B3,$E$2:$F$465,2,FALSE) -> 15 | E3: HU15308809 | F3: 2
A4: HU15308816 | B4: HU12324718 | C4: =VLOOKUP(A4,$E$2:$F$465,2,FALSE) -> 3 | D4: =VLOOKUP(B4,$E$2:$F$465,2,FALSE) -> 16 | E4: HU15308816 | F4: 3
A5: HU15308816 | B5: HU10476015 | C5: =VLOOKUP(A5,$E$2:$F$465,2,FALSE) -> 3 | D5: =VLOOKUP(B5,$E$2:$F$465,2,FALSE) -> 17 | E5: HU19308681 | F5: 4
A6: HU15308816 | B6: HU12497278 | C6: =VLOOKUP(A6,$E$2:$F$465,2,FALSE) -> 3 | D6: =VLOOKUP(B6,$E$2:$F$465,2,FALSE) -> 18 | E6: HU19308650 | F6: 5
A7: HU15308816 | B7: HU12497340 | C7: =VLOOKUP(A7,$E$2:$F$465,2,FALSE) -> 3 | D7: =VLOOKUP(B7,$E$2:$F$465,2,FALSE) -> 19 | E7: HU19294784 | F7: 6
A8: HU15308816 | B8: HU13978774-B0005 | C8: =VLOOKUP(A8,$E$2:$F$465,2,FALSE) -> 3 | D8: =VLOOKUP(B8,$E$2:$F$465,2,FALSE) -> 20 | E8: HU15308902 | F8: 7
A9: HU15308816 | B9: HU12620667 | C9: =VLOOKUP(A9,$E$2:$F$465,2,FALSE) -> 3 | D9: =VLOOKUP(B9,$E$2:$F$465,2,FALSE) -> 21 | E9: HU19308708 | F9: 8
A10: HU15308816 | B10: HU13108809 | C10: =VLOOKUP(A10,$E$2:$F$465,2,FALSE) -> 3 | D10: =VLOOKUP(B10,$E$2:$F$465,2,FALSE) -> 22 | E10: HU15320988 | F10: 9
A11: HU15308816 | B11: HU13978774 | C11: =VLOOKUP(A11,$E$2:$F$465,2,FALSE) -> 3 | D11: =VLOOKUP(B11,$E$2:$F$465,2,FALSE) -> 23 | E11: HU15834474 | F11: 10
A12: HU15308816 | B12: HU14198418 | C12: =VLOOKUP(A12,$E$2:$F$465,2,FALSE) -> 3 | D12: =VLOOKUP(B12,$E$2:$F$465,2,FALSE) -> 24 | E12: HU19253086 | F12: 11
A13: HU15308816 | B13: HU14482270 | C13: =VLOOKUP(A13,$E$2:$F$465,2,FALSE) -> 3 | D13: =VLOOKUP(B13,$E$2:$F$465,2,FALSE) -> 25 | E13: HU15834481 | F13: 12
... A465: HU19308667 | B465: HU11804262 | C465: =VLOOKUP(A465,$E$2:$F$465,2,FALSE) -> 1 | D465: =VLOOKUP(B465,$E$2:$F$465,2,FALSE) -> 448 | E465: HU18491263 | F465: 464
A466: HU19308667 | B466: HU12203949 | C466: =VLOOKUP(A466,$E$2:$F$465,2,FALSE) -> 1 | D466: =VLOOKUP(B466,$E$2:$F$465,2,FALSE) -> 449
A467: HU19308667 | B467: HU12537288 | C467: =VLOOKUP(A467,$E$2:$F$465,2,FALSE) -> 1 | D467: =VLOOKUP(B467,$E$2:$F$465,2,FALSE) -> 329
A468: HU19308667 | B468: HU25438330 | C468: =VLOOKUP(A468,$E$2:$F$465,2,FALSE) -> 1 | D468: =VLOOKUP(B468,$E$2:$F$465,2,FALSE) -> 450
A469: HU19308667 | B469: HU18544488 | C469: =VLOOKUP(A469,$E$2:$F$465,2,FALSE) -> 1 | D469: =VLOOKUP(B469,$E$2:$F$465,2,FALSE) -> 451
A470: HU19308667 | B470: HU18824182 | C470: =VLOOKUP(A470,$E$2:$F$465,2,FALSE) -> 1 | D470: =VLOOKUP(B470,$E$2:$F$465,2,FALSE) -> 452
A471: HU19308667 | B471: HU14028793 | C471: =VLOOKUP(A471,$E$2:$F$465,2,FALSE) -> 1 | D471: =VLOOKUP(B471,$E$2:$F$465,2,FALSE) -> 453
A472: HU19308667 | B472: HU14026825 | C472: =VLOOKUP(A472,$E$2:$F$465,2,FALSE) -> 1 | D472: =VLOOKUP(B472,$E$2:$F$465,2,FALSE) -> 454
A473: HU19308667 | B473: HU22693224 | C473: =VLOOKUP(A473,$E$2:$F$465,2,FALSE) -> 1 | D473: =VLOOKUP(B473,$E$2:$F$465,2,FALSE) -> 455
A474: HU19308667 | B474: HU23357255 | C474: =VLOOKUP(A474,$E$2:$F$465,2,FALSE) -> 1 | D474: =VLOOKUP(B474,$E$2:$F$465,2,FALSE) -> 456
A475: HU19308667 | B475: HU14838286 | C475: =VLOOKUP(A475,$E$2:$F$465,2,FALSE) -> 1 | D475: =VLOOKUP(B475,$E$2:$F$465,2,FALSE) -> 457
A476: HU19308667 | B476: HU10575482 | C476: =VLOOKUP(A476,$E$2:$F$465,2,FALSE) -> 1 | D476: =VLOOKUP(B476,$E$2:$F$465,2,FALSE) -> 415
A477: HU19308667 | B477: HU24381541 | C477: =VLOOKUP(A477,$E$2:$F$465,2,FALSE) -> 1 | D477: =VLOOKUP(B477,$E$2:$F$465,2,FALSE) -> 458
... A485: HU15320988 | B485: HU18491263 | C485: =VLOOKUP(A485,$E$2:$F$465,2,FALSE) -> 9 | D485: =VLOOKUP(B485,$E$2:$F$465,2,FALSE) -> 464

Sheet Lenevezések
A1: Rövidítés | B1: Angol elnevezés | C1: Magyar elnevezés
A2: DCI | B2: Indegree centrality | C2: Bejövő fokszámközpontiság
A3: DCO | B3: Outdegree centrality | C3: Kimenő fokszámközpontiság
A4: DC | B4: Degree centrality | C4: Fokszámközpontiság
A5: BC | B5: Betweenness centrality | C5: Köztességi központiság
A6: CC | B6: Closeness centrality | C6: Közelségi központiság
A7: HC | B7: Harmonic centrality | C7: Harmonikus központiság
A8: EC | B8: Eignevector centrality | C8: Sajátvektor központiság
A9: AUT | B9: Authoritty score | C9: Autoritás érték
A10: HBS | B10: Hub score | C10: Hub érték
A11: PRC | B11: PageRank centrality | C11: PageRank központiság
A12: AC | B12: Alpha centrality | C12: Alfa központiság
... A17: SCR | B17: S-core value | C17: S-mag érték

Sheet szótár2
A1: Egyetemek/cégek | B1: BvD ID | G1: eddig | H1: most
A2: Debreceni Egyetem | B2: HU19308667 | C2: 1 | F2: =497-464 -> 33 | G2: =SUM(G3:G30) -> 46 | H2: =SUM(H3:H30) -> 33
A3: Miskolci Egyetem | B3: HU15308809 | C3: 2 | F3: zala megyei | G3: 3 | H3: 1
A4: Pannon Egyetem | B4: HU15308816 | C4: 3 | F4: statcog | G4: 2 | H4: 1
A5: Pécsi Tudományegyetem | B5: HU19308681 | C5: 4 | F5: agrartudományi kut | G5: 1 | H5: 1
A6: Szegedi Tudományegyetem | B6: HU19308650 | C6: 5 | F6: itc | G6: 4 | H6: 1
A7: Magyar Agrár- és Élettudományi Egyetem | B7: HU19294784 | C7: 6 | F7: delta | G7: 9 | H7: 5
A8: Széchenyi István Egyetem | B8: HU15308902 | C8: 7 | F8: ah net | G8: 2 | H8: 1
A9: Nyíregyházi Egyetem | B9: HU19308708 | C9: 8 | F9: agroit | G9: 1 | H9: 1
A10: Dunaújvárosi Egyetem | B10: HU15320988 | C10: 9 | F10: mediner | G10: 1 | H10: 1
A11: Neumann János Egyetem | B11: HU15834474 | C11: 10 | F11: holl | G11: 1 | H11: 1
A12: Soproni Egyetem | B12: HU19253086 | C12: 11 | F12: adu alba | G12: 1 | H12: 1
A13: Eszterházy Károly Egyetem | B13: HU15834481 | C13: 12 | F13: "kata cnc" | G13: 1 | H13: 1
A14: Budapesti egyetemek | B14: Budapesti | C14: 13 | F14: orgonmed | G14: 1 | H14: 1
... A30: NN ENERGETIKAI MEGOLDASOK KORLATOLT FELELOSSEGU TARSASAG | B30: HU23460027 | C30: 29 | F30: biotalentum | G30: 1 | H30: 1
A31: MKB BANK PLC. - BUDAPEST | B31: HU10011922 | C31: 30
A32: VFP SYSTEMS KERESKEDELMI ES SZOLGALTATO KORLATOLT FELELOSSEGU TARSASAG | B32: HU23806072 | C32: 31
A33: BIOCENTRUM KORNYEZETVEDELMI ES VIZGAZDALKODASI KORLATOLT FELELOSSEGU TARSASAG | B33: HU23833650 | C33: 32
A34: FLEXMONT SZERELESTECHNIKAI ES AUTOMATIZALASI KORLATOLT FELELOSSEGU TARSASAG | B34: HU24378776 | C34: 33
A35: NAGYKANIZSAI KERESKEDELMI ES IPARKAMARA | B35: HU25151873 | C35: 34
A36: SQS 2001. KERESKEDELMI ES SZOLGALTATO KORLATOLT FELELOSSEGU TARSASAG | B36: HU26248699 | C36: 35
A37: VIRGO SYSTEMS INFORMATIKAI KORLATOLT FELELOSSEGU TARSASAG | B37: HU27942592 | C37: 36
A38: PROMERA MENEDZSMENT KORLATOLT FELELOSSEGU TARSASAG | B38: HU29158188 | C38: 37
A39: ZALA MEGYEI KERESKEDELMI ES IPARKAMARA SZOLGALTATO KORLATOLT FELELOSSEGU TARSASAG | B39: HU26250061 | C39: 38
A40: HOLL & MOOR EGESZSEGUGYI SZOLGALTATO ES TANACSADO KORLATOLT FELELOSSEGU TARSASAG | B40: HU24918688 | C40: 39
A41: ORGONMED KORLATOLT FELELOSSEGU TARSASAG | B41: HU14953925 | C41: 40
A42: PANNON INNOVATION AGENCY KORLATOLT FELELOSSEGU TARSASAG | B42: HU11164511 | C42: 41
... A452: "3T" RESEARCH KUTATASFEJLESZTO, KERESKEDELMI ES SZOLGALTATO KORLATOLT FELELOSSEGU TARSASAG | B452: HU18491263 | C452: 451
A453: MORGAN STAR GROUP KERESKEDELMI KORLATOLT FELELOSSEGU TARSASAG | C453: 452
A454: RIPASSA KORLATOLT FELELOSSEGU TARSASAG | C454: 453
A455: INNOVATIV ELELMISZERIPARI KLASZTER KORLATOLT FELELOSSEGU TARSASAG | C455: 454
A456: SEROTECH INNOVACIOS KORLATOLT FELELOSSEGU TARSASAG | C456: 455
A457: DEBTECH LTD | C457: 456
A458: SZABOLCS-SZATMAR-BEREG MEGYEI KERESKEDELMI ES IPARKAMARA | C458: 457
A459: VAMAV VASUTI BERENDEZESEK KORLATOLT FELELOSSEGU TARSASAG | C459: 458
A460: TEMERIT CSOSZERELO ES TARTALYGYARTO KORLATOLT FELELOSSEGU TARSASAG | C460: 459
A461: FEJER MEGYEI KERESKEDELMI ES IPARKAMARA NONPROFIT KORLATOLT FELELOSSEGU TARSASAGA | C461: 460
A462: DUNAUJVAROS MEGYEI JOGU VAROS KERESKEDELMI ES IPARKAMARA | C462: 461

Sheet from_to2
A1: Honnan (Egyetem) | B1: Hova (cég)
A2: HU15308816 | B2: HU11753795
A3: HU15308816 | B3: HU11912345
A4: HU15308816 | B4: HU12324718
A5: HU15308816 | B5: HU12407954
A6: HU15308816 | B6: HU12497278
A7: HU15308816 | B7: HU12497340
A8: HU15308816 | B8: HU13978774-B0005
A9: HU15308816 | B9: HU12620667
A10: HU15308816 | B10: HU13108809
A11: HU15308816 | B11: HU13978774
A12: HU15308816 | B12: HU14198418
... A485: HU15320988 | B485: HU18491263

Sheet eredeti_szótár
A1: Egyetemek/cégek | B1: BvD ID | C1: No. | D1: Egyetem | H1: BvD ID: Több budapesti egyetem szerepel együtt, csak "budapesti"
A2: Debreceni Egyetem | B2: HU19308667 | C2: 1
A3: Miskolci Egyetem | B3: HU15308809 | C3: 2
A4: Pannon Egyetem | B4: HU15308816 | C4: 3
A5: Pécsi Tudományegyetem | B5: HU19308681 | C5: 4
A6: Szegedi Tudományegyetem | B6: HU19308650 | C6: 5
A7: Magyar Agrár- és Élettudományi Egyetem | B7: HU19294784 | C7: 6
A8: Széchenyi István Egyetem | B8: HU15308902 | C8: 7
A9: Nyíregyházi Egyetem | B9: HU19308708 | C9: 8
A10: Dunaújvárosi Egyetem | B10: HU15320988 | C10: 9
A11: Neumann János Egyetem | B11: HU15834474 | C11: 10
A12: Soproni Egyetem | B12: HU19253086 | C12: 11
A13: Eszterházy Károly Egyetem | B13: HU15834481 | C13: 12
A14: Budapesti egyetemek | B14: Budapesti | C14: 13
A15: CONTROLSOFT-AUTOMATIKA SZOLGALTATO KORLATOLT FELELOSSEGU TARSASAG | B15: HU11753795 | C15: 14 | D15: HU15308816
A16: BAY ZOLTAN ALKALMAZOTT KUTATASI KOZHASZNU NONPROFIT KORLATOLT FELELOSSEGU TARSASAG | B16: HU11912345 | C16: 15 | D16: HU15308816
A17: HIDROFILT VIZKEZELEST TERVEZO ES KIVITELEZO KORLATOLT FELELOSSEGU TARSASAG | B17: HU12324718 | C17: 16 | D17: HU15308816
A18: AGRARTUDOMANYI KUTATOKOZPONT | B18: HU10476015 | C18: 17 | D18: HU15308816
A19: GONDOS AGRIKULTURA KORLATOLT FELELOSSEGU TARSASAG | B19: HU12497278 | C19: 18 | D19: HU15308816
A20: KDRIU KOZEP-DUNANTULI REGIONALIS INNOVACIOS UGYNOKSEG NONPROFIT KORLATOLT FELELOSSEGU TARSASAG | B20: HU12497340 | C20: 19 | D20: HU15308816
A21: DELTA SYSTEMS KORLATOLT FELELOSSEGU TARSASAG - VESZPREM | B21: HU13978774-B0005 | C21: 20 | D21: HU15308816
A22: LAVINA SZERVIZ KERESKEDELMI ES SZOLGALTATO KORLATOLT FELELOSSEGU TARSASAG | B22: HU12620667 | C22: 21 | D22: HU15308816
A23: MOL MAGYAR OLAJ-ES GAZIPARE RESZVENYTAR | B23: HU13108809 | C23: 22 | D23: HU15308816
A24: ADIENT MEZOLAK KORLATOLT FELELOSSEGU TARSASAG | B24: HU13978774 | C24: 23 | D24: HU15308816
A25: NAGYKANIZSA VAGYONGAZDALKODASI ES SZOLGALTATO ZARTKORUEN MUKODO RESZVENYTARSASAG | B25: HU14198418 | C25: 24 | D25: HU15308816
A26: MAGYAR KORUT KORLATOLT FELELOSSEGU TARSASAG | B26: HU14482270 | C26: 25 | D26: HU15308816
... A498: DUNAUJVAROS MEGYEI JOGU VAROS KERESKEDELMI ES IPARKAMARA | B498: HU18491263 | C498: 497 | D498: HU15320988

Sheet eredeti_from-to
A1: Honnan (Egyetem) | B1: Hova (TIP) | C1: From | D1: To | G1: Honnan: Több budapesti egyetem szerepel együtt, csak "budapesti"
A2: HU15308816 | B2: HU11753795 | C2: =VLOOKUP(A2,eredeti_szótár!$B$2:$C$498,2,FALSE) -> 3 | D2: =VLOOKUP(B2,eredeti_szótár!$B$2:$C$498,2,FALSE) -> 14
A3: HU15308816 | B3: HU11912345 | C3: =VLOOKUP(A3,eredeti_szótár!$B$2:$C$498,2,FALSE) -> 3 | D3: =VLOOKUP(B3,eredeti_szótár!$B$2:$C$498,2,FALSE) -> 15
A4: HU15308816 | B4: HU12324718 | C4: =VLOOKUP(A4,eredeti_szótár!$B$2:$C$498,2,FALSE) -> 3 | D4: =VLOOKUP(B4,eredeti_szótár!$B$2:$C$498,2,FALSE) -> 16
A5: HU15308816 | B5: HU12407954 | C5: =VLOOKUP(A5,eredeti_szótár!$B$2:$C$498,2,FALSE) -> 3 | D5: =VLOOKUP(B5,eredeti_szótár!$B$2:$C$498,2,FALSE) -> #N/A
A6: HU15308816 | B6: HU12497278 | C6: =VLOOKUP(A6,eredeti_szótár!$B$2:$C$498,2,FALSE) -> 3 | D6: =VLOOKUP(B6,eredeti_szótár!$B$2:$C$498,2,FALSE) -> 18
A7: HU15308816 | B7: HU12497340 | C7: =VLOOKUP(A7,eredeti_szótár!$B$2:$C$498,2,FALSE) -> 3 | D7: =VLOOKUP(B7,eredeti_szótár!$B$2:$C$498,2,FALSE) -> 19
A8: HU15308816 | B8: HU12539558 | C8: =VLOOKUP(A8,eredeti_szótár!$B$2:$C$498,2,FALSE) -> 3 | D8: =VLOOKUP(B8,eredeti_szótár!$B$2:$C$498,2,FALSE) -> #N/A
A9: HU15308816 | B9: HU12620667 | C9: =VLOOKUP(A9,eredeti_szótár!$B$2:$C$498,2,FALSE) -> 3 | D9: =VLOOKUP(B9,eredeti_szótár!$B$2:$C$498,2,FALSE) -> 21
A10: HU15308816 | B10: HU13108809 | C10: =VLOOKUP(A10,eredeti_szótár!$B$2:$C$498,2,FALSE) -> 3 | D10: =VLOOKUP(B10,eredeti_szótár!$B$2:$C$498,2,FALSE) -> 22
A11: HU15308816 | B11: HU13978774 | C11: =VLOOKUP(A11,eredeti_szótár!$B$2:$C$498,2,FALSE) -> 3 | D11: =VLOOKUP(B11,eredeti_szótár!$B$2:$C$498,2,FALSE) -> 23
A12: HU15308816 | B12: HU14198418 | C12: =VLOOKUP(A12,eredeti_szótár!$B$2:$C$498,2,FALSE) -> 3 | D12: =VLOOKUP(B12,eredeti_szótár!$B$2:$C$498,2,FALSE) -> 24
A13: HU15308816 | B13: HU14482270 | C13: =VLOOKUP(A13,eredeti_szótár!$B$2:$C$498,2,FALSE) -> 3 | D13: =VLOOKUP(B13,eredeti_szótár!$B$2:$C$498,2,FALSE) -> 25
... A543: HU15320988 | B543: HU18491263 | C543: =VLOOKUP(A543,eredeti_szótár!$B$2:$C$498,2,FALSE) -> 9 | D543: =VLOOKUP(B543,eredeti_szótár!$B$2:$C$498,2,FALSE) -> 497
